<?xml version="1.0"?>

<robot xmlns:xacro="http://ros.org/wiki/xacro">

  <xacro:macro name="s4_gun" params="prefix parent pos_x pos_z">
    <joint name="${prefix}/base1_joint" type="fixed">
      <parent link="${parent}"/>
      <child link="${prefix}/base1_link"/>
      <origin rpy="0 0 0" xyz="${pos_x} 0 ${pos_z}"/>
    </joint>
    <link name="${prefix}/base1_link">
      <visual>
        <origin xyz="0 0 0" rpy="0 0 0"/>
        <geometry>
          <mesh filename="package://s4_description/stl/gun_base1.stl" />
        </geometry>
        <material name="gray"/>
      </visual>
      <inertial>
        <mass value="0.130"/>
        <inertia ixx="0.0001" ixy="0" ixz="0" iyy="0.0001" iyz="0" izz="0.0001"/>
      </inertial>  
    </link>

    <joint name="${prefix}/base2_joint" type="continuous">
      <parent link="${prefix}/base1_link"/>
      <child link="${prefix}/base2_link"/>
      <origin rpy="0 0 0" xyz="0 0 0.016"/>
      <axis xyz="0 0 1"/>
      <dynamics damping="0.7"/>
    </joint>
    <link name="${prefix}/base2_link">
      <visual>
        <origin xyz="0 0 0" rpy="0 0 0"/>
        <geometry>
          <mesh filename="package://s4_description/stl/gun_base2.stl" />
        </geometry>
        <material name="gray"/>
      </visual>
      <inertial>
        <mass value="0.190"/>
        <inertia ixx="0.001" ixy="0" ixz="0" iyy="0.001" iyz="0" izz="0.0001"/>
      </inertial>  
    </link>
    <transmission name="${prefix}/base2_trans">
      <type>transmission_interface/SimpleTransmission</type>
      <joint name="${prefix}/base2_joint">
        <hardwareInterface>hardware_interface/EffortJointInterface</hardwareInterface>
      </joint>
      <actuator name="${prefix}/base2_motor">
        <hardwareInterface>hardware_interface/EffortJointInterface</hardwareInterface>
        <mechanicalReduction>1</mechanicalReduction>
      </actuator>
    </transmission>

    <joint name="${prefix}/gun_joint" type="continuous">
      <parent link="${prefix}/base2_link"/>
      <child link="${prefix}/gun_link"/>
      <origin rpy="0 0 0" xyz="0 0 0.070"/>
      <axis xyz="0 1 0"/>
      <dynamics damping="0.1"/>
    </joint>
    <link name="${prefix}/gun_link">
      <visual>
        <origin xyz="0 0 0" rpy="0 0 0"/>
        <geometry>
          <mesh filename="package://s4_description/stl/gun_barrel.stl" />
        </geometry>
        <material name="light_red"/>
      </visual>
      <inertial>
        <mass value="0.190"/>
        <inertia ixx="0.0001" ixy="0" ixz="0" iyy="0.001" iyz="0" izz="0.001"/>
      </inertial>  
    </link>
    <transmission name="${prefix}/gun_trans">
      <type>transmission_interface/SimpleTransmission</type>
      <joint name="${prefix}/gun_joint">
        <hardwareInterface>hardware_interface/EffortJointInterface</hardwareInterface>
      </joint>
      <actuator name="${prefix}/gun_motor">
        <hardwareInterface>hardware_interface/EffortJointInterface</hardwareInterface>
        <mechanicalReduction>1</mechanicalReduction>
      </actuator>
    </transmission>
    <gazebo reference="${prefix}/gun_link">
      <material>Gazebo/Blue</material>
    </gazebo>

    <joint name="${prefix}/laser_joint" type="fixed">
      <parent link="${prefix}/gun_link"/>
      <child link="${prefix}/laser_link"/>
      <origin rpy="0 0 0" xyz="0.030 0 -0.034"/>
    </joint>
    <link name="${prefix}/laser_link"/>

    <joint name="${prefix}/standard_joint" type="fixed">
      <parent link="${prefix}/base1_link"/>
      <child  link="${prefix}/gun_standard"/>
      <origin rpy="0 0 0" xyz="0 0 0.086"/>
    </joint>
    <link name="${prefix}/gun_standard" />

  </xacro:macro>
</robot>
