<?xml version="1.0"?>
<robot name="my_robot">
  <link name="world"/>
  <link name="base_link"/>
  <joint name="robot_joint" type="floating">
    <parent link="world"/>
    <child link="base_link"/>
    <origin xyz="0 0 0" rpy="0 0 0"/>
    <axis xyz="0 0 1"/>
    <limit effort="30" velocity="1.0" lower="-2.0" upper="2.0" />
  </joint>

  <link name="body_link">
    <visual>
      <origin rpy="0 0 0" xyz="0 0 0.05"/>
      <geometry>
        <cylinder radius="0.15" length="0.10" />
      </geometry>
    </visual>
  </link>
  <joint name="body_joint" type="fixed">
    <parent link="base_link"/>
    <child link="body_link"/>
    <origin xyz="0 0 0.038" rpy="0 0 0"/>
    <axis xyz="0 0 1"/>
    <limit effort="30" velocity="1.0" lower="-2.0" upper="2.0" />
  </joint>

  <link name="wheel0_link">
    <visual>
      <origin rpy="0 0 0" xyz="0 0 0"/>
      <geometry>
        <cylinder radius="0.019" length="0.02" />
      </geometry>
    </visual>
  </link>
  <joint name="wheel0_joint" type="continuous">
    <parent link="base_link"/>
    <child link="wheel0_link"/>
    <origin xyz="0.07 0.121 0.019" rpy="0 1.5707 1.047"/>
    <axis xyz="0 0 1"/>
    <limit effort="30" velocity="1.0" lower="-2.0" upper="2.0" />
  </joint>

  <link name="wheel1_link">
    <visual>
      <origin rpy="0 0 0" xyz="0 0 0"/>
      <geometry>
        <cylinder radius="0.019" length="0.02" />
      </geometry>
    </visual>
  </link>
  <joint name="wheel1_joint" type="continuous">
    <parent link="base_link"/>
    <child link="wheel1_link"/>
    <origin xyz="-0.14 0 0.019" rpy="0 1.5707 3.1415"/>
    <axis xyz="0 0 1"/>
    <limit effort="30" velocity="1.0" lower="-2.0" upper="2.0" />
  </joint>

  <link name="wheel2_link">
    <visual>
      <origin rpy="0 0 0" xyz="0 0 0"/>
      <geometry>
        <cylinder radius="0.019" length="0.02" />
      </geometry>
    </visual>
  </link>
  <joint name="wheel2_joint" type="continuous">
    <parent link="base_link"/>
    <child link="wheel2_link"/>
    <origin xyz="0.07 -0.121 0.019" rpy="0 1.5707 -1.047"/>
    <axis xyz="0 0 1"/>
    <limit effort="30" velocity="1.0" lower="-2.0" upper="2.0" />
  </joint>

</robot>
