<?xml version="1.0"?>
<robot xmlns:xacro="http://ros.org/wiki/xacro">
  <xacro:macro name="s4_vive_controller" params="prefix parent">
    <link name="${prefix}/body_link">
      <visual>
        <origin rpy="0 0 0" xyz="0 0 0"/>
        <geometry>
          <mesh filename="package://s4_vive/stl/vive_controller.stl"/>
        </geometry>
        <material name="green">
          <color rgba="0 1 0 1"/>
        </material>
      </visual>
    </link>
    <joint name="${prefix}/body_joint" type="floating">
      <parent link="${parent}"/>
      <child  link="${prefix}/body_link"/>
      <origin xyz="0 0 0" rpy="0 0 0"/>
      <axis xyz="0 0 1"/>
      <limit effort="30" velocity="1.0" lower="-2.0" upper="2.0" />
    </joint>
    <link name="${prefix}/pointer_link" />
    <joint name="${prefix}/controller0/pointer0_joint" type="fixed">
      <parent link="${prefix}/body_link"/>
      <child  link="${prefix}/pointer_link"/>
      <origin xyz="0 0 -0.0685" rpy="0 1.01 0"/>
      <axis xyz="0 0 1"/>
      <limit effort="30" velocity="1.0" lower="-2.0" upper="2.0" />
    </joint>
    <link name="${prefix}/goal_link" />
    <joint name="${prefix}/goal_joint" type="floating">
      <parent link="${prefix}/pointer_link"/>
      <child  link="${prefix}/goal_link"/>
      <origin xyz="0 0 0" rpy="0 0 0"/>
      <axis xyz="0 0 1"/>
      <limit effort="30" velocity="1.0" lower="-2.0" upper="2.0" />
    </joint>
  </xacro:macro>
</robot>
